Workbook

Sheet Calculator
B1: Warren Bros Fencing - Cedar Fence Material Calculator
B2: Prices from B&B Lumber + Home Depot (06/05/2026). Yellow cells = your inputs.
B4: JOB INPUTS
B5: Total fence length (linear feet) | C5: 100
B6: Fence height (ft) | C6: 6
B7: Picket style | C7: 1x8x6' Premium Heavy 7/8in (21mm)
B8: Gap between pickets (in) [0 = full privacy] | C8: 0
B9: Number of rails | C9: 3
B10: Rail board | C10: 2x4x8' Cedar Fence Rail S4S
B11: Post spacing (ft on-center) | C11: 8
B12: Post type | C12: 4x4x8' Cedar Post
B13: Concrete mix | C13: Quikrete 60 lb bag
B14: Bags of concrete per post [0 if driving posts] | C14: 2
B15: Include kickboard / rot board? | C15: No
B16: Kickboard board (if Yes) | C16: 2x6x8' Rough Cedar (kickboard)
B17: Waste / breakage % | C17: 0.1
B18: Sales tax % | C18: 0.075
B20: Assumption - picket actual width (in) | C20: 7.5 | D20: (1x8 = 7.5in)
B22: MATERIAL TAKEOFF
B23: Material | C23: Qty | D23: U/M | E23: Unit Price | F23: Line Cost
B24: Pickets | C24: =ROUNDUP(ROUNDUP($C$5*12/($C$20+$C$8),0)*(1+$C$17),0) -> 176 | D24: EA | E24: =INDEX('Price List'!$E:$E,MATCH($C$7,'Price List'!$A:$A,0)) -> 6.36 | F24: =C24*E24 -> 1119.36
B25: Rails | C25: =ROUNDUP($C$5*$C$9/INDEX('Price List'!$G:$G,MATCH($C$10,'Price List'!$A:$A,0))*(1+$C$17),0) -> 42 | D25: EA | E25: =INDEX('Price List'!$E:$E,MATCH($C$10,'Price List'!$A:$A,0)) -> 6.96 | F25: =C25*E25 -> 292.32
B26: Posts | C26: =ROUNDUP($C$5/$C$11,0)+1 -> 14 | D26: EA | E26: =INDEX('Price List'!$E:$E,MATCH($C$12,'Price List'!$A:$A,0)) -> 11.98 | F26: =C26*E26 -> 167.72
B27: Concrete (bags) | C27: =ROUNDUP($C$14*C26,0) -> 28 | D27: BAG | E27: =INDEX('Price List'!$E:$E,MATCH($C$13,'Price List'!$A:$A,0)) -> 4.68 | F27: =C27*E27 -> 131.04
B28: Kickboard / rot board | C28: =IF($C$15="Yes",ROUNDUP($C$5/INDEX('Price List'!$G:$G,MATCH($C$16,'Price List'!$A:$A,0)),0),0) -> 0 | D28: EA | E28: =INDEX('Price List'!$E:$E,MATCH($C$16,'Price List'!$A:$A,0)) -> 28 | F28: =C28*E28 -> 0
E29: Subtotal | F29: =SUM(F24:F28) -> 1710.44
E30: Sales tax | F30: =F29*$C$18 -> 128.283
E31: TOTAL MATERIAL | F31: =F29+F30 -> 1838.723
E32: Material cost / linear ft | F32: =F31/$C$5 -> 18.38723
B34: BID BUILDER (cost + overhead + margin)
B35: Labor rate ($ / person-hour) | C35: 60
B36: Crew size (people) | C36: 2
B37: Productivity (linear ft / clock-hour) | C37: 20 | E37: clock hrs: | F37: =IF($C$37=0,0,ROUND($C$5/$C$37,1)) -> 5
B38: Overhead % (insurance, truck, fuel, tools, mktg) | C38: 0.25
B39: Target profit margin % | C39: 0.3
B40: Number of gates | C40: 0
B41: Price per gate (material + labor, $) | C41: 250
B42: Tear-out / haul-off old fence ($) | C42: 0
B43: Hard dig / rock / slope adder ($) | C43: 0
B45: BID CALCULATION
...

Sheet Price List
A1: Display Name | B1: Code | C1: Description | D1: Unit | E1: Price | F1: Category | G1: Length (ft) | H1: Source
A2: 1x8x6' Premium Heavy 7/8in (21mm) | B2: 186CHD | C2: FENCE 1X8X6' 7/8in CEDAR DOG EARRED PREMIUM 21mm | D2: EA | E2: 6.36 | F2: Picket | G2: 6 | H2: B&B
A3: 1x8x6' Medium 23/32in (18mm) | B3: 186CMD | C3: FENCE 1X8X6' 23/32in CEDAR DOG EARRED 18MM | D3: EA | E3: 5.68 | F3: Picket | G3: 6 | H3: B&B
A4: 1x8x6' Select 5/8in (15mm) | B4: 186SELECT | C4: FENCE 1X8X6' 5/8in 15mm CEDAR Dog Earred | D4: EA | E4: 4.72 | F4: Picket | G4: 6 | H4: B&B
A5: 1x8x8' Select 5/8in (15mm) | B5: 188SELECT | C5: FENCE 1X8X8' 5/8in 15mm CEDAR Dog Earred | D5: EA | E5: 7.25 | F5: Picket | G5: 8 | H5: B&B
A6: 1x8x8' Heavy 7/8in (21mm) | B6: 188CHD | C6: FENCE 1X8X8'HVY 7/8in 21mm CEDAR FENCE | D6: EA | E6: 9.6 | F6: Picket | G6: 8 | H6: B&B
A7: 2x4x8' Cedar Fence Rail S4S | B7: 2408CFR | C7: 2 X 4-08 CEDAR FENCE RAIL S4S GRN STD&BTR NO HOLE | D7: EA | E7: 6.96 | F7: Rail | G7: 8 | H7: B&B
A8: 2x4x10' Cedar Fence Rail S4S | B8: 2410CFR | C8: 2 X 4-10 CEDAR FENCE RAIL S4S | D8: EA | E8: 10.34 | F8: Rail | G8: 10 | H8: B&B
A9: 2x4x8' Rough Cedar | B9: 2408C | C9: CED- 2 X 4-08 ROUGH CEDAR | D9: EA | E9: 13.87 | F9: Rail | G9: 8 | H9: B&B
A10: 2x4x8' Smooth Cedar S4S | B10: 2408CS4S | C10: CED- 2 X 4-08 SMOOTH CEDAR S4S | D10: EA | E10: 11.41 | F10: Rail | G10: 8 | H10: B&B
A11: Metal U-Post 8' G-90 | B11: PMS8 | C11: METAL U-SHAPED 8' G-90 POST | D11: EA | E11: 36.98 | F11: Post | G11: 8 | H11: B&B
A12: Metal U-Post 10' G-90 | B12: PMS10 | C12: METAL U-SHAPED 10' G-90 POST | D12: EA | E12: 42.99 | F12: Post | G12: 10 | H12: B&B
A13: Post Terminal 2-3/8in x 8' | B13: 8MP | C13: POST TERMINAL .065 2-3/8INX8FT | D13: EA | E13: 18.75 | F13: Post | G13: 8 | H13: B&B
... A19: 2x6x16' Rough Cedar (kickboard) | B19: 2616C | C19: CED- 2 X 6-16 ROUGH CEDAR | D19: EA | E19: 59.2 | F19: Kickboard | G19: 16 | H19: B&B
A20: Quikrete 60 lb bag | B20: QUIK60 | C20: Quikrete Fast-Setting Concrete Mix, 60 lb | D20: BAG | E20: 4.68 | F20: Concrete | H20: Home Depot
A21: Quikrete 80 lb bag | B21: QUIK80 | C21: Quikrete Fast-Setting Concrete Mix, 80 lb | D21: BAG | E21: 6.24 | F21: Concrete | H21: Home Depot
A22: 1x4x8' Cedar (trim/cap) | B22: 1408C | C22: CED- 1 X 4-08 #3 & BTR S1S2E CEDAR | D22: EA | E22: 8.01 | F22: Trim | G22: 8 | H22: B&B
A23: 1x4x16' Cedar (trim/cap) | B23: 1416C | C23: CED- 1 X 4-16 #3 & BTR S1S2E CEDAR | D23: EA | E23: 16.53 | F23: Trim | G23: 16 | H23: B&B
A25: Sources: B&B Lumber Quote #2606-664566 (Wichita KS, 06/05/2026, expired 06/08/2026) for pickets, rails, metal posts, kickboard, trim. Home Depot (06/05/2026) for 4x4 cedar posts and Quikrete. All prices per-unit, before tax. Re-verify before bidding.

Sheet Notes & Assumptions
A1: Warren Bros Fencing - Cedar Fence Material Calculator
A3: HOW TO USE
A4: Fill in the yellow cells on the Calculator tab. Everything else calculates automatically.
A5: Pick picket / rail / post / concrete / kickboard from the dropdowns (sourced from the Price List tab).
A7: FORMULAS
A8: Pickets = roundup( length_ft x 12 / (picket_width + gap) ) x (1 + waste), rounded up.
A9: Picket actual width defaults to 7.5in (a 1x8 board). Gap 0 = full privacy.
A10: Rails = roundup( length_ft x number_of_rails / rail_board_length ) x (1 + waste).
A11: Posts = roundup( length_ft / post_spacing ) + 1 end post.
A12: Concrete = bags_per_post x posts. Set bags per post to 0 if you drive metal posts.
A13: Kickboard = roundup( length_ft / board_length ), only if set to Yes.
A15: BID BUILDER - how the quote is priced
... A38: Prices are date-stamped - re-confirm before bidding a real job.
